<?xml version="1.0" encoding="UTF-8"?>
<!-- Generated by org.testng.reporters.JUnitReportReporter -->
<testsuite skipped="0" hostname="L-SJC-10005066" name="rest.automation.netflix.TestClass" tests="1" failures="1" timestamp="13 Feb 2017 04:10:02 GMT" time="0.955" errors="0">
  <testcase name="TestValidateResponse" time="0.955" classname="rest.automation.netflix.TestClass">
    <failure type="java.lang.AssertionError" message="unit not matches expected [35] but found [352]">
      <![CDATA[java.lang.AssertionError: unit not matches expected [35] but found [352]
	at org.testng.Assert.fail(Assert.java:94)
	at org.testng.Assert.failNotEquals(Assert.java:513)
	at org.testng.Assert.assertEqualsImpl(Assert.java:135)
	at org.testng.Assert.assertEquals(Assert.java:116)
	at org.testng.Assert.assertEquals(Assert.java:389)
	at rest.automation.netflix.TestClass.validateResponse(TestClass.java:68)
	at rest.automation.netflix.TestClass.TestValidateResponse(TestClass.java:46)
	at sun.reflect.NativeMethodAccessorImpl.invoke0(Native Method)
	at sun.reflect.NativeMethodAccessorImpl.invoke(Unknown Source)
	at sun.reflect.DelegatingMethodAccessorImpl.invoke(Unknown Source)
	at java.lang.reflect.Method.invoke(Unknown Source)
	at org.testng.internal.MethodInvocationHelper.invokeMethod(MethodInvocationHelper.java:100)
	at org.testng.internal.Invoker.invokeMethod(Invoker.java:646)
	at org.testng.internal.Invoker.invokeTestMethod(Invoker.java:811)
	at org.testng.internal.Invoker.invokeTestMethods(Invoker.java:1137)
	at org.testng.internal.TestMethodWorker.invokeTestMethods(TestMethodWorker.java:129)
	at org.testng.internal.TestMethodWorker.run(TestMethodWorker.java:112)
	at org.testng.TestRunner.privateRun(TestRunner.java:753)
	at org.testng.TestRunner.run(TestRunner.java:607)
	at org.testng.SuiteRunner.runTest(SuiteRunner.java:368)
	at org.testng.SuiteRunner.runSequentially(SuiteRunner.java:363)
	at org.testng.SuiteRunner.privateRun(SuiteRunner.java:321)
	at org.testng.SuiteRunner.run(SuiteRunner.java:270)
	at org.testng.SuiteRunnerWorker.runSuite(SuiteRunnerWorker.java:52)
	at org.testng.SuiteRunnerWorker.run(SuiteRunnerWorker.java:86)
	at org.testng.TestNG.runSuitesSequentially(TestNG.java:1284)
	at org.testng.TestNG.runSuitesLocally(TestNG.java:1209)
	at org.testng.TestNG.runSuites(TestNG.java:1124)
	at org.testng.TestNG.run(TestNG.java:1096)
	at org.testng.remote.AbstractRemoteTestNG.run(AbstractRemoteTestNG.java:126)
	at org.testng.remote.RemoteTestNG.initAndRun(RemoteTestNG.java:152)
	at org.testng.remote.RemoteTestNG.main(RemoteTestNG.java:57)
]]>
    </failure>
  </testcase> <!-- TestValidateResponse -->
</testsuite> <!-- rest.automation.netflix.TestClass -->
